"""
Реализуйте декоратор exception_decorator, который возвращает кортеж (value, 'Функция выполнилась без ошибок'),
если декорируемая функция завершила свою работу без ошибок, где value — возвращаемое значение декорируемой функции
кортеж (None, 'При вызове функции произошла ошибка'), если при выполнении декорируемой функции возникла ошибка
Примечание 1. Не забывайте про то, что декоратор не должен поглощать возвращаемое значение декорируемой функции,
а также должен уметь декорировать функции с произвольным количеством позиционных и именованных аргументов.
"""


def exception_decorator(func):
    def wrapper(*args, **kwargs):
        try:
            result = func(*args, **kwargs)
            return result, 'Функция выполнилась без ошибок'
        except Exception as err:
            return None, 'При вызове функции произошла ошибка'

    return wrapper


sum = exception_decorator(sum)

print(sum(['199', '1', 187]))
